Traceback (most recent call last):
  File "/home/varun/.espressif/python_env/idf5.4_py3.10_env/lib/python3.10/site-packages/serial/serialposix.py", line 621, in write
    n = os.write(self.fd, d)
OSError: [Errno 5] Input/output error

During handling of the above exception, another exception occurred:

Traceback (most recent call last):
  File "/home/varun/.espressif/python_env/idf5.4_py3.10_env/lib/python3.10/site-packages/esptool/loader.py", line 465, in command
    self.write(pkt)
  File "/home/varun/.espressif/python_env/idf5.4_py3.10_env/lib/python3.10/site-packages/esptool/loader.py", line 418, in write
    self._port.write(buf)
  File "/home/varun/.espressif/python_env/idf5.4_py3.10_env/lib/python3.10/site-packages/serial/serialposix.py", line 655, in write
    raise SerialException('write failed: {}'.format(e))
serial.serialutil.SerialException: write failed: [Errno 5] Input/output error

During handling of the above exception, another exception occurred:

Traceback (most recent call last):
  File "/home/varun/.espressif/python_env/idf5.4_py3.10_env/lib/python3.10/site-packages/serial/serialposix.py", line 398, in _reconfigure_port
    orig_attr = termios.tcgetattr(self.fd)
termios.error: (5, 'Input/output error')

During handling of the above exception, another exception occurred:

Traceback (most recent call last):
  File "/home/varun/.espressif/python_env/idf5.4_py3.10_env/lib/python3.10/site-packages/esptool/cmds.py", line 654, in write_flash
    esp.flash_defl_block(block, seq, timeout=timeout)
  File "/home/varun/.espressif/python_env/idf5.4_py3.10_env/lib/python3.10/site-packages/esptool/loader.py", line 127, in inner
    return func(*args, **kwargs)
  File "/home/varun/.espressif/python_env/idf5.4_py3.10_env/lib/python3.10/site-packages/esptool/loader.py", line 1186, in flash_defl_block
    self.check_command(
  File "/home/varun/.espressif/python_env/idf5.4_py3.10_env/lib/python3.10/site-packages/esptool/loader.py", line 506, in check_command
    val, data = self.command(op, data, chk, timeout=timeout)
  File "/home/varun/.espressif/python_env/idf5.4_py3.10_env/lib/python3.10/site-packages/esptool/loader.py", line 493, in command
    self._port.timeout = saved_timeout
  File "/home/varun/.espressif/python_env/idf5.4_py3.10_env/lib/python3.10/site-packages/serial/serialutil.py", line 372, in timeout
    self._reconfigure_port()
  File "/home/varun/.espressif/python_env/idf5.4_py3.10_env/lib/python3.10/site-packages/serial/serialposix.py", line 401, in _reconfigure_port
    raise SerialException("Could not configure port: {}".format(msg))
serial.serialutil.SerialException: Could not configure port: (5, 'Input/output error')

During handling of the above exception, another exception occurred:

Traceback (most recent call last):
  File "/usr/lib/python3.10/runpy.py", line 196, in _run_module_as_main
    return _run_code(code, main_globals, None,
  File "/usr/lib/python3.10/runpy.py", line 86, in _run_code
    exec(code, run_globals)
  File "/home/varun/.espressif/python_env/idf5.4_py3.10_env/lib/python3.10/site-packages/esptool/__main__.py", line 9, in <module>
    esptool._main()
  File "/home/varun/.espressif/python_env/idf5.4_py3.10_env/lib/python3.10/site-packages/esptool/__init__.py", line 1359, in _main
    main()
  File "/home/varun/.espressif/python_env/idf5.4_py3.10_env/lib/python3.10/site-packages/esptool/__init__.py", line 1063, in main
    operation_func(esp, args)
  File "/home/varun/.espressif/python_env/idf5.4_py3.10_env/lib/python3.10/site-packages/esptool/cmds.py", line 683, in write_flash
    esp.connect()
  File "/home/varun/.espressif/python_env/idf5.4_py3.10_env/lib/python3.10/site-packages/esptool/loader.py", line 726, in connect
    last_error = self._connect_attempt(reset_strategy, mode)
  File "/home/varun/.espressif/python_env/idf5.4_py3.10_env/lib/python3.10/site-packages/esptool/loader.py", line 617, in _connect_attempt
    self.flush_input()
  File "/home/varun/.espressif/python_env/idf5.4_py3.10_env/lib/python3.10/site-packages/esptool/loader.py", line 531, in flush_input
    self._port.flushInput()
  File "/home/varun/.espressif/python_env/idf5.4_py3.10_env/lib/python3.10/site-packages/serial/serialutil.py", line 588, in flushInput
    self.reset_input_buffer()
  File "/home/varun/.espressif/python_env/idf5.4_py3.10_env/lib/python3.10/site-packages/serial/serialposix.py", line 683, in reset_input_buffer
    self._reset_input_buffer()
  File "/home/varun/.espressif/python_env/idf5.4_py3.10_env/lib/python3.10/site-packages/serial/serialposix.py", line 677, in _reset_input_buffer
    termios.tcflush(self.fd, termios.TCIFLUSH)
termios.error: (5, 'Input/output error')
CMake Error at run_serial_tool.cmake:67 (message):
  
  /home/varun/.espressif/python_env/idf5.4_py3.10_env/bin/python;;/home/varun/esp/esp-idf/components/esptool_py/esptool/esptool.py;--chip;esp32
  failed.



